Traceback (most recent call last):
  File "/home/runner/work/cvx_stat_arb/cvx_stat_arb/.venv/lib/python3.10/site-packages/jupyter_cache/executors/utils.py", line 58, in single_nb_execution
    executenb(
  File "/home/runner/work/cvx_stat_arb/cvx_stat_arb/.venv/lib/python3.10/site-packages/nbclient/client.py", line 1305, in execute
    return NotebookClient(nb=nb, resources=resources, km=km, **kwargs).execute()
  File "/home/runner/work/cvx_stat_arb/cvx_stat_arb/.venv/lib/python3.10/site-packages/jupyter_core/utils/__init__.py", line 166, in wrapped
    return loop.run_until_complete(inner)
  File "/opt/hostedtoolcache/Python/3.10.11/x64/lib/python3.10/asyncio/base_events.py", line 649, in run_until_complete
    return future.result()
  File "/home/runner/work/cvx_stat_arb/cvx_stat_arb/.venv/lib/python3.10/site-packages/nbclient/client.py", line 705, in async_execute
    await self.async_execute_cell(
  File "/home/runner/work/cvx_stat_arb/cvx_stat_arb/.venv/lib/python3.10/site-packages/nbclient/client.py", line 1058, in async_execute_cell
    await self._check_raise_for_error(cell, cell_index, exec_reply)
  File "/home/runner/work/cvx_stat_arb/cvx_stat_arb/.venv/lib/python3.10/site-packages/nbclient/client.py", line 914, in _check_raise_for_error
    raise CellExecutionError.from_cell_and_msg(cell, exec_reply_content)
nbclient.exceptions.CellExecutionError: An error occurred while executing the following cell:
------------------
portfolio = builder(
    prices=prices,
    initial_cash=1e6,
    market_cap=market_cap,
    trade_volume=volume,
    weights=weights,
    max_cap_fraction=0.06,  # position max 6% of market cap
    max_trade_fraction=0.2, # trade max 20% of daily volume
).build()

------------------


[0;31m---------------------------------------------------------------------------[0m
[0;31mTypeError[0m                                 Traceback (most recent call last)
Cell [0;32mIn[6], line 1[0m
[0;32m----> 1[0m portfolio [38;5;241m=[39m [43mbuilder[49m[43m([49m
[1;32m      2[0m [43m    [49m[43mprices[49m[38;5;241;43m=[39;49m[43mprices[49m[43m,[49m
[1;32m      3[0m [43m    [49m[43minitial_cash[49m[38;5;241;43m=[39;49m[38;5;241;43m1e6[39;49m[43m,[49m
[1;32m      4[0m [43m    [49m[43mmarket_cap[49m[38;5;241;43m=[39;49m[43mmarket_cap[49m[43m,[49m
[1;32m      5[0m [43m    [49m[43mtrade_volume[49m[38;5;241;43m=[39;49m[43mvolume[49m[43m,[49m
[1;32m      6[0m [43m    [49m[43mweights[49m[38;5;241;43m=[39;49m[43mweights[49m[43m,[49m
[1;32m      7[0m [43m    [49m[43mmax_cap_fraction[49m[38;5;241;43m=[39;49m[38;5;241;43m0.06[39;49m[43m,[49m[43m  [49m[38;5;66;43;03m# position max 6% of market cap[39;49;00m
[1;32m      8[0m [43m    [49m[43mmax_trade_fraction[49m[38;5;241;43m=[39;49m[38;5;241;43m0.2[39;49m[43m,[49m[43m [49m[38;5;66;43;03m# trade max 20% of daily volume[39;49;00m
[1;32m      9[0m [43m)[49m[38;5;241m.[39mbuild()

[0;31mTypeError[0m: builder() got an unexpected keyword argument 'market_cap'

